2024-01-28 15:04:52,205 INFO    StreamThr :24521 [internal.py:wandb_internal():86] W&B internal server running at pid: 24521, started at: 2024-01-28 15:04:52.204803
2024-01-28 15:04:52,206 DEBUG   HandlerThread:24521 [handler.py:handle_request():146] handle_request: status
2024-01-28 15:04:52,207 INFO    WriterThread:24521 [datastore.py:open_for_write():87] open: /home/arvindcar/MAIL_Lab/VINN/VINN-Sculpt/VINN-ACT/wandb/run-20240128_150452-527g4b09/run-527g4b09.wandb
2024-01-28 15:04:52,207 DEBUG   SenderThread:24521 [sender.py:send():382] send: header
2024-01-28 15:04:52,210 DEBUG   SenderThread:24521 [sender.py:send():382] send: run
2024-01-28 15:04:52,435 ERROR   SenderThread:24521 [internal_api.py:execute():373] 403 response executing GraphQL.
2024-01-28 15:04:52,435 ERROR   SenderThread:24521 [internal_api.py:execute():374] {"errors":[{"message":"permission denied","path":["upsertBucket"],"extensions":{"code":"PERMISSION_ERROR"}}],"data":{"upsertBucket":null}}
2024-01-28 15:04:52,435 ERROR   SenderThread:24521 [sender.py:send_run():987] It appears that you do not have permission to access the requested resource. Please reach out to the project owner to grant you access. If you have the correct permissions, verify that there are no issues with your networking setup.(Error 403: Forbidden)
Traceback (most recent call last):
  File "/home/arvindcar/.local/lib/python3.10/site-packages/wandb/sdk/lib/retry.py", line 131, in __call__
    result = self._call_fn(*args, **kwargs)
  File "/home/arvindcar/.local/lib/python3.10/site-packages/wandb/sdk/internal/internal_api.py", line 369, in execute
    return self.client.execute(*args, **kwargs)  # type: ignore
  File "/home/arvindcar/.local/lib/python3.10/site-packages/wandb/vendor/gql-0.2.0/wandb_gql/client.py", line 52, in execute
    result = self._get_result(document, *args, **kwargs)
  File "/home/arvindcar/.local/lib/python3.10/site-packages/wandb/vendor/gql-0.2.0/wandb_gql/client.py", line 60, in _get_result
    return self.transport.execute(document, *args, **kwargs)
  File "/home/arvindcar/.local/lib/python3.10/site-packages/wandb/sdk/lib/gql_request.py", line 59, in execute
    request.raise_for_status()
  File "/usr/lib/python3/dist-packages/requests/models.py", line 943, in raise_for_status
    raise HTTPError(http_error_msg, response=self)
requests.exceptions.HTTPError: 403 Client Error: Forbidden for url: https://api.wandb.ai/graphql

During handling of the above exception, another exception occurred:

Traceback (most recent call last):
  File "/home/arvindcar/.local/lib/python3.10/site-packages/wandb/sdk/internal/sender.py", line 985, in send_run
    self._init_run(run, config_value_dict)
  File "/home/arvindcar/.local/lib/python3.10/site-packages/wandb/sdk/internal/sender.py", line 1027, in _init_run
    server_run, inserted, server_messages = self._api.upsert_run(
  File "/home/arvindcar/.local/lib/python3.10/site-packages/wandb/apis/normalize.py", line 73, in wrapper
    raise err
  File "/home/arvindcar/.local/lib/python3.10/site-packages/wandb/apis/normalize.py", line 41, in wrapper
    return func(*args, **kwargs)
  File "/home/arvindcar/.local/lib/python3.10/site-packages/wandb/sdk/internal/internal_api.py", line 2216, in upsert_run
    response = self.gql(
  File "/home/arvindcar/.local/lib/python3.10/site-packages/wandb/sdk/internal/internal_api.py", line 341, in gql
    ret = self._retry_gql(
  File "/home/arvindcar/.local/lib/python3.10/site-packages/wandb/sdk/lib/retry.py", line 147, in __call__
    retry_timedelta_triggered = check_retry_fn(e)
  File "/home/arvindcar/.local/lib/python3.10/site-packages/wandb/util.py", line 965, in check_retry_fn
    return fallback_retry_fn(e)
  File "/home/arvindcar/.local/lib/python3.10/site-packages/wandb/util.py", line 907, in no_retry_auth
    raise CommError(
wandb.errors.CommError: It appears that you do not have permission to access the requested resource. Please reach out to the project owner to grant you access. If you have the correct permissions, verify that there are no issues with your networking setup.(Error 403: Forbidden)
2024-01-28 15:04:52,650 DEBUG   HandlerThread:24521 [handler.py:handle_request():146] handle_request: shutdown
2024-01-28 15:04:52,650 INFO    HandlerThread:24521 [handler.py:finish():869] shutting down handler
2024-01-28 15:04:53,210 INFO    WriterThread:24521 [datastore.py:close():296] close: /home/arvindcar/MAIL_Lab/VINN/VINN-Sculpt/VINN-ACT/wandb/run-20240128_150452-527g4b09/run-527g4b09.wandb
2024-01-28 15:04:53,439 INFO    SenderThread:24521 [sender.py:finish():1572] shutting down sender
